Workbook

Sheet 正解一覧
A1: 令和8年度 確認テスト 正解一覧（採点用）
A2: 問1〜5は○×、問6〜10はア・イ・ウ。1問1点・10点満点。7点以上が目安です。★は法定研修。
A4: 月 | B4: 研修テーマ | C4: 問1 | D4: 問2 | E4: 問3 | F4: 問4 | G4: 問5 | H4: 問6 | I4: 問7 | J4: 問8 | K4: 問9 | L4: 問10
A5: 4月 | B5: 運営規程・倫理・法令遵守、個人情報保護 | C5: ○ | D5: × | E5: ○ | F5: × | G5: × | H5: イ | I5: ウ | J5: イ | K5: イ | L5: ウ
A6: 5月 | B6: ★高齢者虐待防止・身体的拘束等の適正化（第1回） | C6: ○ | D6: ○ | E6: × | F6: ○ | G6: × | H6: イ | I6: ウ | J6: ウ | K6: ア | L6: ア
A7: 6月 | B7: ★感染症の予防及びまん延防止 | C7: ○ | D7: × | E7: ○ | F7: ○ | G7: × | H7: イ | I7: イ | J7: イ | K7: ウ | L7: イ
A8: 7月 | B8: ★業務継続計画（自然災害）＋訓練 | C8: ○ | D8: ○ | E8: × | F8: ○ | G8: × | H8: イ | I8: イ | J8: ウ | K8: ウ | L8: イ
A9: 8月 | B9: 事故防止・緊急時対応 | C9: ○ | D9: × | E9: ○ | F9: ○ | G9: × | H9: イ | I9: ア | J9: ウ | K9: ア | L9: ウ
A10: 9月 | B10: ハラスメント対策 | C10: ○ | D10: ○ | E10: ○ | F10: × | G10: × | H10: イ | I10: イ | J10: ウ | K10: ウ | L10: イ
A11: 10月 | B11: 認知症ケア・接遇 | C11: ○ | D11: ○ | E11: × | F11: ○ | G11: × | H11: イ | I11: イ | J11: イ | K11: イ | L11: ウ
A12: 11月 | B12: ★業務継続計画（感染症）＋感染症訓練 | C12: ○ | D12: ○ | E12: ○ | F12: × | G12: × | H12: ウ | I12: ウ | J12: イ | K12: イ | L12: ア
A13: 12月 | B13: ★高齢者虐待防止（第2回）・事例検討 | C13: ○ | D13: ○ | E13: ○ | F13: × | G13: × | H13: ウ | I13: イ | J13: ウ | K13: イ | L13: イ
A14: 1月 | B14: 介護技術・医行為の範囲 | C14: ○ | D14: × | E14: × | F14: ○ | G14: ○ | H14: イ | I14: ア | J14: イ | K14: イ | L14: イ
A15: 2月 | B15: 看取り・プライバシー保護 | C15: ○ | D15: × | E15: ○ | F15: ○ | G15: × | H15: ア | I15: ア | J15: ア | K15: イ | L15: ア
A16: 3月 | B16: 年間振り返り・次年度計画 | C16: ○ | D16: ○ | E16: × | F16: ○ | G16: × | H16: ウ | I16: イ | J16: ア | K16: イ | L16: ア

Sheet 解答・解説
A1: 確認テスト 解答・解説（管理者・講師用）
A3: 月 | B3: 問 | C3: 形式 | D3: 問題 | E3: 選択肢 | F3: 正解 | G3: 解説
A4: 4月 運営規程・倫理・法令遵守、個人情報保護
A5: 4月 | B5: 1 | C5: ○× | D5: 運営規程には、虐待防止のための措置に関する事項も定められている。 | F5: ○ | G5: 運営規程には事業の目的、利用料、緊急時の対応、虐待防止の措置などが定められています。
A6: 4月 | B6: 2 | C6: ○× | D6: 利用者の名前を伏せれば、利用者宅での出来事をSNSに書いてもよい。 | F6: × | G6: 名前を伏せても本人が特定されるおそれがあります。業務上知り得たことはSNSに書きません。
A7: 4月 | B7: 3 | C7: ○× | D7: 訪問介護員は、訪問介護計画とサービス提供手順書に沿って支援する。 | F7: ○ | G7: 計画と手順書がサービス提供の根拠です。
A8: 4月 | B8: 4 | C8: ○× | D8: 利用者宅の写真を、私物のスマートフォンで撮影してよい。 | F8: × | G8: 私物の端末での撮影は個人情報漏えいの原因になります。
A9: 4月 | B9: 5 | C9: ○× | D9: サービス提供記録は「特変なし」とだけ書けば十分である。 | F9: × | G9: 食事量、表情、会話など観察したことを具体的に書きます。
A10: 4月 | B10: 6 | C10: 三択 | D10: 重要事項説明書について正しいものはどれか。 | E10: ア 契約した後で渡せばよい イ 契約の前に説明し、同意を得る ウ 職員だけが見る内部の書類である | F10: イ | G10: 重要事項説明書は契約前に利用者に説明し、同意を得る書類です。
A11: 4月 | B11: 7 | C11: 三択 | D11: 訪問介護計画にない大掃除を頼まれたときの対応はどれか。 | E11: ア その場で引き受ける イ 何も言わずに帰る ウ サービス提供責任者に相談する | F11: ウ | G11: 計画にない支援は自己判断で行わず、サービス提供責任者に相談します。
A12: 4月 | B12: 8 | C12: 三択 | D12: 守秘義務について正しいものはどれか。 | E12: ア 在職中だけ守ればよい イ 退職した後も守る ウ 管理者だけに課される | F12: イ | G12: 守秘義務は退職後も続きます。
A13: 4月 | B13: 9 | C13: 三択 | D13: 記録を書き間違えたときの正しい訂正方法はどれか。 | E13: ア 修正液で消して書き直す イ 二重線を引き、訂正者名を書く ウ 黒く塗りつぶす | F13: イ | G13: 訂正は二重線と訂正者名で行い、元の記載が読めるようにします。
A14: 4月 | B14: 10 | C14: 三択 | D14: 介護職の倫理として不適切な行為はどれか。 | E14: ア 利用者を「〇〇さん」と呼ぶ イ 体調不良のときに報告して訪問を控える ウ 利用者に頼まれて私的な連絡先を交換する | F14: ウ | G14: 私的な連絡先の交換や個人的な頼まれごとはしません。
A16: 5月 ★高齢者虐待防止・身体的拘束等の適正化（第1回）
A17: 5月 | B17: 1 | C17: ○× | D17: 高齢者虐待防止法の対象は、65歳以上の高齢者である。 | F17: ○ | G17: 法律上の「高齢者」は65歳以上の人です。
A18: 5月 | B18: 2 | C18: ○× | D18: 時間がないからと必要な排泄介助を省くことは、介護・世話の放棄・放任にあたりうる。 | F18: ○ | G18: 必要な介護をしないことは「介護・世話の放棄・放任」にあたります。
A19: 5月 | B19: 3 | C19: ○× | D19: 虐待の通報は、必ず事業所を通して行わなければならない。 | F19: × | G19: 事業所への報告が基本ですが、職員が直接市町村へ通報することも認められています。
A20: 5月 | B20: 4 | C20: ○× | D20: 身体的拘束等を行った場合は、態様・時間・心身の状況・理由を記録する。 | F20: ○ | G20: 令和6年度改定で、訪問介護でも記録が義務づけられました。
A21: 5月 | B21: 5 | C21: ○× | D21: 不適切ケアは、虐待とは関係がない。 | F21: × | G21: 虐待は「これくらいなら」という不適切ケアの積み重ねから起こります。
A22: 5月 | B22: 6 | C22: 三択 | D22: 経済的虐待にあたるものはどれか。 | E22: ア 利用者を怒鳴る イ 買い物のおつりを返さない ウ おむつを長時間替えない | F22: イ | G22: 財産を不当に使うことは経済的虐待です。アは心理的虐待、ウは介護・世話の放棄・放任です。
A23: 5月 | B23: 7 | C23: 三択 | D23: 身体拘束の例外となる3要件に含まれないものはどれか。 | E23: ア 切迫性 イ 非代替性 ウ 家族の希望 | F23: ウ | G23: 3要件は「切迫性」「非代替性」「一時性」です。家族の希望は要件ではありません。
A24: 5月 | B24: 8 | C24: 三択 | D24: 家族がベッド柵で四方を囲んでいることに気づいたときの対応はどれか。 | E24: ア 黙って柵を外す イ 見なかったことにする ウ サービス提供責任者に報告し、ケアマネジャーと連携する | F24: ウ | G24: 自己判断で外したり見過ごしたりせず、報告して連携します。
A25: 5月 | B25: 9 | C25: 三択 | D25: 家族による虐待で、生命・身体に重大な危険が生じている場合はどうするか。 | E25: ア 市町村への通報義務がある イ 通報してはいけない ウ しばらく様子を見る | F25: ア | G25: 重大な危険が生じている場合は通報義務があります。
A26: 5月 | B26: 10 | C26: 三択 | D26: 心理的虐待にあたるものはどれか。 | E26: ア 話しかけを無視する イ 腕を強く引っ張る ウ 預金を勝手に使う | F26: ア | G26: 無視や暴言は心理的虐待です。イは身体的虐待、ウは経済的虐待です。
A28: 6月 ★感染症の予防及びまん延防止
A29: 6月 | B29: 1 | C29: ○× | D29: 訪問介護員は、感染症を利用者宅から別の利用者宅へ運ぶおそれがある。 | F29: ○ | G29: 1日に複数の利用者宅を回るため、感染の媒介になるおそれがあります。
A30: 6月 | B30: 2 | C30: ○× | D30: 石けんでの手洗いは10秒程度で十分である。 | F30: × | G30: 30秒以上かけて、指の間、指先・爪、親指、手首まで洗います。
A31: 6月 | B31: 3 | C31: ○× | D31: 手袋は1ケアごとに交換する。 | F31: ○ | G31: 同じ手袋で別のケアをすると感染を広げます。
A32: 6月 | B32: 4 | C32: ○× | D32: 嘔吐物を処理するときは、窓を開けて換気する。 | F32: ○ | G32: ノロウイルスなどは空気中に舞うことがあるため換気します。
A33: 6月 | B33: 5 | C33: ○× | D33: 結核の主な感染経路は接触感染である。 | F33: × | G33: 結核は空気感染します。長引く咳は受診につなげます。
A34: 6月 | B34: 6 | C34: 三択 | D34: 標準予防策を行う対象はどれか。 | E34: ア 感染症と診断された利用者だけ イ すべての利用者 ウ 発熱のある利用者だけ | F34: イ | G34: 診断の有無にかかわらず、すべての利用者に行います。
A35: 6月 | B35: 7 | C35: 三択 | D35: ノロウイルスの消毒に有効なものはどれか。 | E35: ア アルコール イ 次亜塩素酸ナトリウム ウ 水拭き | F35: イ | G35: ノロウイルスにはアルコールが効きにくく、次亜塩素酸ナトリウムを使います。
A36: 6月 | B36: 8 | C36: 三択 | D36: 嘔吐物を処理した床を覆う次亜塩素酸ナトリウム液の濃度はどれか。 | E36: ア 0.01% イ 0.1% ウ 1% | F36: イ | G36: 0.1%の液を浸したペーパーで覆い、約10分置いて拭きます。
A37: 6月 | B37: 9 | C37: 三択 | D37: 手洗いの後に手を拭くものとして適切なものはどれか。 | E37: ア 利用者宅のタオル イ 自分のハンカチ ウ 使い捨てペーパータオル | F37: ウ | G37: タオルの共用は感染の原因になるため、使い捨てペーパータオルを使います。
A38: 6月 | B38: 10 | C38: 三択 | D38: 出勤前に発熱していたときの対応はどれか。 | E38: ア 訪問が終わってから報告する イ 訪問せず管理者に連絡する ウ 解熱剤を飲んで訪問する | F38: イ | G38: 発熱・下痢・嘔吐があるときは訪問せず、管理者に連絡します。
A40: 7月 ★業務継続計画（自然災害）＋訓練
A41: 7月 | B41: 1 | C41: ○× | D41: BCPは、災害時にもサービスを止めない、または早く再開するための計画である。 | F41: ○ | G41: BCPは業務継続計画のことです。
A42: 7月 | B42: 2 | C42: ○× | D42: BCPが策定されていない場合、介護報酬が減算される。 | F42: ○ | G42: 業務継続計画未策定減算の対象になります。
A43: 7月 | B43: 3 | C43: ○× | D43: 災害時の利用者の安否確認は、名簿の五十音順に行う。 | F43: × | G43: 独居、医療機器使用など優先度の高い利用者から確認します。
A44: 7月 | B44: 4 | C44: ○× | D44: 夏季に停電が起きたときは、熱中症に注意する。 | F44: ○ | G44: 水分補給と涼しい場所の確保を優先します。
...

Sheet 振り返りクイズ解答
A1: 研修資料 末尾の振り返りクイズ（○×5問）の解答
A3: 月 | B3: 番号 | C3: 問題 | D3: 正解 | E3: 補足
A4: 4月 | B4: 1 | C4: 退職した後であれば、利用者の情報を話しても問題ない。 | D4: × | E4: 退職後も守秘義務がある
A5: 4月 | B5: 2 | C5: 利用者から感謝の気持ちとして渡された現金は、少額であれば受け取ってよい。 | D5: × | E5: 金額にかかわらず受け取らない
A6: 4月 | B6: 3 | C6: ケアマネジャーに利用者の情報を伝えるには、あらかじめ文書による同意が必要である。 | D6: ○
A7: 4月 | B7: 4 | C7: 訪問介護計画にない支援を頼まれたら、サービス提供責任者に相談する。 | D7: ○
A8: 4月 | B8: 5 | C8: 記録の誤りは修正液で消して書き直す。 | D8: × | E8: 二重線と訂正者名で訂正する
A9: 5月 | B9: 1 | C9: 介護職員が利用者に「早くして」と怒鳴ることは、心理的虐待にあたる可能性がある。 | D9: ○
A10: 5月 | B10: 2 | C10: 職員による虐待を見つけても、確証がなければ通報してはいけない。 | D10: × | E10: 疑いの段階で報告・通報する
A11: 5月 | B11: 3 | C11: 虐待を通報した職員が、それを理由に解雇されることはない。 | D11: ○
A12: 5月 | B12: 4 | C12: 身体的拘束等は、家族の同意があればいつでも行ってよい。 | D12: × | E12: 3要件を満たす緊急やむを得ない場合のみ、記録も必要
A13: 5月 | B13: 5 | C13: 利用者の買い物のおつりを返さないことは、経済的虐待にあたる。 | D13: ○
A14: 6月 | B14: 1 | C14: 標準予防策は、感染症と診断された利用者にだけ行う。 | D14: × | E14: すべての利用者に行う
A15: 6月 | B15: 2 | C15: 手袋を外した後も手指衛生が必要である。 | D15: ○
A16: 6月 | B16: 3 | C16: ノロウイルスの消毒には、アルコールよりも次亜塩素酸ナトリウムが有効である。 | D16: ○
A17: 6月 | B17: 4 | C17: 少し熱があっても、訪問の予定があれば連絡せずに出勤する。 | D17: × | E17: 訪問せず管理者に連絡する
A18: 6月 | B18: 5 | C18: 利用者宅のタオルで手を拭くのは問題ない。 | D18: × | E18: 使い捨てペーパータオルを使う
A19: 7月 | B19: 1 | C19: BCPの研修と訓練は、それぞれ年1回以上行う必要がある。 | D19: ○
A20: 7月 | B20: 2 | C20: 訪問中に地震が起きたら、利用者を残してすぐに自宅へ戻る。 | D20: × | E20: 安全確保後、事業所の指示を受ける
A21: 7月 | B21: 3 | C21: 安否確認は、独居や医療機器を使う利用者など優先度の高い人から行う。 | D21: ○
A22: 7月 | B22: 4 | C22: 災害時は職員が足りなくても、全てのサービスを通常どおり提供しなければならない。 | D22: × | E22: 優先業務に絞って提供する
A23: 7月 | B23: 5 | C23: 災害用伝言ダイヤルの番号は171である。 | D23: ○
A24: 8月 | B24: 1 | C24: ヒヤリハットは事故ではないので報告しなくてよい。 | D24: × | E24: 事故防止のために報告・共有する
A25: 8月 | B25: 2 | C25: 転倒して痛みを訴える利用者は、すぐに起こしてベッドに戻す。 | D25: × | E25: 無理に動かさず状態を確認し事業所に連絡する
A26: 8月 | B26: 3 | C26: 服薬介助では、薬を飲み込むまで見届ける。 | D26: ○
A27: 8月 | B27: 4 | C27: 訪問して応答がないときは、合鍵があれば自己判断で中に入る。 | D27: × | E27: 事業所に連絡し指示を受ける
A28: 8月 | B28: 5 | C28: 事故が起きたら、事業所は家族やケアマネジャー、市町村に連絡する。 | D28: ○
A29: 9月 | B29: 1 | C29: 利用者から身体を触られても、我慢して最後までサービスを行うべきである。 | D29: × | E29: 安全を優先し、その場を離れてよい
A30: 9月 | B30: 2 | C30: ハラスメントを受けたら、日時と内容を記録して報告する。 | D30: ○
A31: 9月 | B31: 3 | C31: 契約外の家事を繰り返し求められることは、不当な要求にあたりうる。 | D31: ○
A32: 9月 | B32: 4 | C32: 相談したことを理由に、担当から外されたり不利益を受けることがある。 | D32: × | E32: 不利益な扱いは禁止されている
A33: 9月 | B33: 5 | C33: 事業所は、職場のハラスメントについて方針を明確にし、相談体制を整える必要がある。 | D33: ○
A34: 10月 | B34: 1 | C34: BPSDは、体調や環境、周囲の対応の影響を受けて起こる。 | D34: ○
A35: 10月 | B35: 2 | C35: もの盗られ妄想には、事実を説明して納得してもらうのが最も良い。 | D35: × | E35: 否定せず気持ちに寄り添う
A36: 10月 | B36: 3 | C36: 認知症の人に話しかけるときは、正面から目線を合わせて名乗る。 | D36: ○
A37: 10月 | B37: 4 | C37: 親しみを込めて「おばあちゃん」と呼ぶのは良い接遇である。 | D37: × | E37: 「〇〇さん」と呼ぶ
A38: 10月 | B38: 5 | C38: 本人ができることは、時間がかかっても本人にしてもらう。 | D38: ○
A39: 11月 | B39: 1 | C39: 感染症BCPでは、防護具や消毒液の備蓄を平時から準備しておく。 | D39: ○
A40: 11月 | B40: 2 | C40: 感染疑いの利用者の訪問は、なるべく1日の最初にする。 | D40: × | E40: 他の利用者への感染を防ぐため最後にする
A41: 11月 | B41: 3 | C41: 職員が不足した場合は、ケアマネジャーと相談してサービス内容を見直すことがある。 | D41: ○
...

Sheet 採点表
A1: 採点表：月を選び、職員の解答（○×・アイウ）を入れると点数が自動計算されます
A2: 月 | B2: 4月
A3: 正解 | B3: =INDEX(正解一覧!C$5:C$16,MATCH($B$2,正解一覧!$A$5:$A$16,0)) | C3: =INDEX(正解一覧!D$5:D$16,MATCH($B$2,正解一覧!$A$5:$A$16,0)) | D3: =INDEX(正解一覧!E$5:E$16,MATCH($B$2,正解一覧!$A$5:$A$16,0)) | E3: =INDEX(正解一覧!F$5:F$16,MATCH($B$2,正解一覧!$A$5:$A$16,0)) | F3: =INDEX(正解一覧!G$5:G$16,MATCH($B$2,正解一覧!$A$5:$A$16,0)) | G3: =INDEX(正解一覧!H$5:H$16,MATCH($B$2,正解一覧!$A$5:$A$16,0)) | H3: =INDEX(正解一覧!I$5:I$16,MATCH($B$2,正解一覧!$A$5:$A$16,0)) | I3: =INDEX(正解一覧!J$5:J$16,MATCH($B$2,正解一覧!$A$5:$A$16,0)) | ... K3: =INDEX(正解一覧!L$5:L$16,MATCH($B$2,正解一覧!$A$5:$A$16,0))
A4: 氏名 | B4: 問1 | C4: 問2 | D4: 問3 | E4: 問4 | F4: 問5 | G4: 問6 | H4: 問7 | I4: 問8 | J4: 問9 | K4: 問10 | L4: 点数 | M4: 判定
L5: =IF(COUNTA(B5:K5)=0,"",SUMPRODUCT(--(B5:K5=$B$3:$K$3))) | M5: =IF(L5="","",IF(L5>=7,"合格","要フォロー"))
L6: =IF(COUNTA(B6:K6)=0,"",SUMPRODUCT(--(B6:K6=$B$3:$K$3))) | M6: =IF(L6="","",IF(L6>=7,"合格","要フォロー"))
L7: =IF(COUNTA(B7:K7)=0,"",SUMPRODUCT(--(B7:K7=$B$3:$K$3))) | M7: =IF(L7="","",IF(L7>=7,"合格","要フォロー"))
L8: =IF(COUNTA(B8:K8)=0,"",SUMPRODUCT(--(B8:K8=$B$3:$K$3))) | M8: =IF(L8="","",IF(L8>=7,"合格","要フォロー"))
L9: =IF(COUNTA(B9:K9)=0,"",SUMPRODUCT(--(B9:K9=$B$3:$K$3))) | M9: =IF(L9="","",IF(L9>=7,"合格","要フォロー"))
L10: =IF(COUNTA(B10:K10)=0,"",SUMPRODUCT(--(B10:K10=$B$3:$K$3))) | M10: =IF(L10="","",IF(L10>=7,"合格","要フォロー"))
L11: =IF(COUNTA(B11:K11)=0,"",SUMPRODUCT(--(B11:K11=$B$3:$K$3))) | M11: =IF(L11="","",IF(L11>=7,"合格","要フォロー"))
L12: =IF(COUNTA(B12:K12)=0,"",SUMPRODUCT(--(B12:K12=$B$3:$K$3))) | M12: =IF(L12="","",IF(L12>=7,"合格","要フォロー"))
L13: =IF(COUNTA(B13:K13)=0,"",SUMPRODUCT(--(B13:K13=$B$3:$K$3))) | M13: =IF(L13="","",IF(L13>=7,"合格","要フォロー"))
L14: =IF(COUNTA(B14:K14)=0,"",SUMPRODUCT(--(B14:K14=$B$3:$K$3))) | M14: =IF(L14="","",IF(L14>=7,"合格","要フォロー"))
L15: =IF(COUNTA(B15:K15)=0,"",SUMPRODUCT(--(B15:K15=$B$3:$K$3))) | M15: =IF(L15="","",IF(L15>=7,"合格","要フォロー"))
L16: =IF(COUNTA(B16:K16)=0,"",SUMPRODUCT(--(B16:K16=$B$3:$K$3))) | M16: =IF(L16="","",IF(L16>=7,"合格","要フォロー"))
... L34: =IF(COUNTA(B34:K34)=0,"",SUMPRODUCT(--(B34:K34=$B$3:$K$3))) | M34: =IF(L34="","",IF(L34>=7,"合格","要フォロー"))
